Workbook

Sheet test
A1: Question | B1: Answer | C1: A | D1: B | E1: C | G1: Explaniation if needed | H1: Category | I1: Sub Category | J1: File Name pulled from
A2: (Refer to figure 15 FAA-CT-8080-2H) At what time does the visibility improve to greater than 6 statute miles? | B2: B | C2: 051200Z | D2: 051600Z | E2: 051524Z | G2: At 051600Z, the TAF indicates "P6SM," meaning visibility improves to greater than 6 statute miles. | H2: Weather | I2: TAF | J2: TAF2 and KEY
A3: (Refer to figure 15 FAA-CT-8080-2H) What does "BECMG 0522/0524 20013G20KT" indicate? | B3: A | C3: A gradual change occurring between 0522Z and 0524Z. | D3: A temporary change lasting between 0522Z and 0524Z. | E3: A wind shift to 220° at 20 knots occurring at 0522Z. | G3: "BECMG" signifies a gradual change expected during the specified time period. | H3: Weather | I3: TAF | J3: TAF2 and KEY
A4: (Refer to figure 15 FAA-CT-8080-2H) What is the forecasted ceiling at 051200Z? | B4: B | C4: Overcast at 3,000 feet. | D4: Broken at 3,000 feet. | E4: Overcast at 2,000 feet. | G4: "BKN030" indicates a broken layer at 3,000 feet, which is the ceiling. | H4: Weather | I4: TAF | J4: TAF2 and KEY
A5: (Refer to figure 15 FAA-CT-8080-2H) During the period 0600Z to 0606Z, what is the probability of thunderstorms? | B5: C | C5: 60% | D5: 30% | E5: 40% | G5: "PROB40" indicates a 40% probability of thunderstorms and rain. | H5: Weather | I5: TAF | J5: TAF2 and KEY
A6: (Refer to figure 15 FAA-CT-8080-2H) What weather phenomenon is associated with "OVC008CB"? | B6: B | C6: Cumulonimbus clouds with fog. | D6: Cumulonimbus clouds with thunderstorms. | E6: Stratocumulus clouds with light rain. | G6: "CB" signifies cumulonimbus clouds, typically associated with thunderstorms. | H6: Weather | I6: TAF | J6: TAF2 and KEY
A7: (Refer to figure 15 FAA-CT-8080-2H) What visibility is expected during the "TEMPO 0513/0516" period? | B7: A | C7: 1 1/2 statute miles | D7: 5 statute miles | E7: Greater than 6 statute miles | G7: During this temporary period, visibility is reduced to 1 1/2SM due to mist, "BR." | H7: Weather | I7: TAF | J7: TAF2 and KEY
A8: (Refer to figure 15) What is the wind forecast for 0608Z? | B8: C | C8: 140° at 8 knots | D8: 200° at 13 knots, gusting to 20 knots | E8: 210° at 15 knots | G8: At 0608Z, the TAF indicates "21015KT," meaning wind from 210° at 15 knots. | H8: Weather | I8: TAF | J8: TAF2 and KEY
A9: (Refer to figure 15 FAA-CT-8080-2H) What does "P6SM SCT040" mean in the forecast starting at 0608Z? | B9: B | C9: Visibility less than 6 statute miles with scattered clouds at 4,000 feet. | D9: Visibility greater than 6 statute miles with scattered clouds at 4,000 feet. | E9: No significant weather with overcast skies at 4,000 feet. | G9: "P6SM" means visibility is greater than 6 statute miles, and "SCT040" indicates scattered clouds at 4,000 feet. | H9: Weather | I9: TAF | J9: TAF2 and KEY
A10: (Refer to Figure 15 FAA-CT-8080-2H) What is the forecast visibility for KMEM at the beginning of the TAF period (1218Z)? | B10: C | C10: 1 mile | D10: 3 statute miles | E10: 5 statute miles | H10: Weather | I10: TAF | J10: TAF Quiz- key
A11: (Refer to Figure 15 FAA-CT-8080-2H) According to the TAF, what type of weather is expected from 1220Z to 1222Z? | B11: A | C11: Thunderstorms with rain and overcast conditions | D11: Snow showers with overcast conditions | E11: Light rain with scattered clouds | H11: Weather | I11: TAF | J11: TAF Quiz- key
A12: (Refer to Figure 15 FAA-CT-8080-2H) What is the expected wind direction and speed at KMEM from 1222Z onward? | B12: C | C12: 020° at 8 knots | D12: 350° at 12 knots | E12: 330° at 15 knots with gusts to 20 knots | H12: Weather | I12: TAF | J12: TAF Quiz- key
A13: (Refer to Figure 15 FAA-CT-8080-2H) What is the forecast ceiling for KMEM from 1220Z to 1222Z? | B13: A | C13: 800 feet AGL | D13: 1,500 feet AGL | E13: 3,000 feet AGL | H13: Weather | I13: TAF | J13: TAF Quiz- key
A14: (Refer to Figure 15 FAA-CT-8080-2H) When is fog expected to occur according to the TAF? | B14: B | C14: From 1312Z to 1314Z | D14: From 1212Z to 1214Z | E14: From 1306Z to 1308Z | H14: Weather | I14: TAF | J14: TAF Quiz- key
A15: (Refer to Figure 15 FAA-CT-8080-2H) What is the forecast wind direction and speed at KMEM from 1202Z to 1205Z? | B15: A | C15: 350° at 12 knots | D15: 020° at 8 knots | E15: 330° at 15 knots, gusting to 20 knots | H15: Weather | I15: TAF | J15: TAF Quiz- key
A16: (Refer to Figure 15 FAA-CT-8080-2H) The forecast ceiling at KMEM from 1200Z to 1220Z is: | B16: B | C16: Clear skies | D16: Overcast at 800 feet AGL | E16: Broken clouds at 3,000 feet AGL | H16: Weather | I16: TAF | J16: TAF Quiz- key
A17: What factor would tend to increase the density altitude? | B17: B | C17: An increase in barometric pressure | D17: An increase in ambient temperature | E17: A decrease in relative humidity | H17: Weather | J17: Weather MC Test - Key 2
A18: With a low-level temperature inversion with high relative humidity, what weather conditions would you expect? | B18: A | C18: Smooth air, poor visibility, fog, haze, or low clouds | D18: Turbulent air, poor visibility, fog, low stratus type clouds, and showery precipitation | E18: Light wind shear, poor visibility, haze, and light rain | H18: Weather | J18: =J17 -> Weather MC Test - Key 2
A19: What is a temperature inversion? | B19: A | C19: Cold air trapped near the surface under warmer air | D19: Warm air trapped near the surface under cooler air | E19: A rapid drop in temperature with altitude | H19: Weather | J19: =J18 -> Weather MC Test - Key 2
A20: What is the effect of humidity on air density? | B20: B | C20: Increased humidity increases air density. | D20: Increased humidity decreases air density. | E20: Humidity has no effect on air density. | H20: Weather | J20: ='end of unit questions'!J33 -> Weather MC Test - Key 2
A21: What is the primary difference between stable and unstable air? | B21: C | C21: Stable air is always dry, while unstable air is always moist. | D21: Stable air has vertical movement, while unstable air does not. | E21: Stable air is associated with clear weather, while unstable air is associated with thunderstorms. | H21: Weather | J21: =J20 -> Weather MC Test - Key 2
A22: What is the primary characteristic of unstable air? | B22: A | C22: It has vertical movement. | D22: It is always dry. | E22: It is always cold. | H22: Weather | J22: =J21 -> Weather MC Test - Key 2
A23: What is the primary factor that determines the stability of an air mass? | B23: C | C23: The amount of wind. | D23: The altitude of the air mass. | E23: The temperature and moisture content of the air. | H23: Weather | J23: =J22 -> Weather MC Test - Key 2
A24: What are the characteristics of stable air? | B24: B | C24: Poor visibility and intermittent precipitation | D24: Poor visibility and steady precipitation | E24: Good visibility and steady precipitation | H24: Weather | J24: =J23 -> Weather MC Test - Key 2
A25: Which weather reports provide real-time observations? | B25: A | C25: METAR | D25: TAF | E25: SIGMET | H25: Weather | I25: Metar | J25: =J24 -> Weather MC Test - Key 2
A26: How does high humidity affect drone performance? | B26: A | C26: Reduce lift | D26: Increase lift | E26: No effect | H26: Weather | J26: =J25 -> Weather MC Test - Key 2
A27: What type of front often brings thunderstorms and gusty winds? | B27: C | C27: Stationary front | D27: Warm front | E27: Cold Front | H27: Weather | J27: =J26 -> Weather MC Test - Key 2
A28: What situation is most conducive to the formation of radiation fog? | B28: A | C28: Warm, moist air over low, flatland areas on clear calm nights | D28: Moist tropical air moving over cold, offshore water | E28: The movement of cold air over much warmer water | H28: Weather | J28: =J27 -> Weather MC Test - Key 2
A29: The two types of clouds that unmanned aircraft operators should be concerned about are: | B29: C | C29: Standing lenticular and stratocumulus | D29: Nimbostratus and cumulonimbus | E29: Cumulonimbus and standing lenticular | H29: Weather | J29: ='end of unit questions'!J32 -> Weather MC Test - Key 2
A30: Every physical process of weather is accompanied by or is a result of a _____________ | B30: C | C30: Movement of air | D30: Pressure differential | E30: Heat Exchange | H30: Weather | J30: =J29 -> Weather MC Test - Key 2
A31: What is the standard temperature at sea level? | B31: A | C31: 15°C or 59°F | D31: 29.92°C | E31: 1013.2°F | H31: Weather | J31: =J30 -> Weather MC Test - Key 2
A32: The development of thermals depends upon _____________ | B32: B | C32: A counter clockwise circulation of air | D32: Solar Heating | E32: Temperature Inversions | H32: Weather | J32: =J31 -> Weather MC Test - Key 2
A33: Wind Shear can exist at…. | B33: A | C33: All Altitudes | D33: Low Altitudes | E33: High Altitudes | H33: Weather | J33: =J32 -> Weather MC Test - Key 2
A34: A stable air mass is most likely to have which characteristic | B34: C | C34: Showery precipitation | D34: Turbulent Air | E34: Poor surface visibility | H34: Weather | J34: ='end of unit questions'!J31 -> Weather MC Test - Key 2
A35: What would decrease the stability of an air mass? | B35: B | C35: Cooling from below | D35: Warming from below | E35: Decrease in water Vapor | H35: Weather | J35: =J34 -> Weather MC Test - Key 2
A36: The cloud ceiling is at 800ft. What is the highest you can operate your drone? | B36: C | C36: 200 FT AGL | D36: 800 FT AGL | E36: 300 Ft AGL | H36: Weather | J36: =J35 -> Weather MC Test - Key 2
A37: What conditions are necessary for the formation of thunderstorms? | B37: B | C37: High humidity, high Temperatures and cumulus clouds | D37: High humidity, lifting force and unstable conditions | E37: Lifting force, moist air and extensive cloud cover | H37: Weather | J37: =J36 -> Weather MC Test - Key 2
A38: What is the effect of a high-density altitude on aircraft performance? | B38: C | C38: It increases aircraft performance. | D38: It has no effect on aircraft performance. | E38: It decreases aircraft performance. | H38: Weather | J38: =J37 -> Weather MC Test - Key 2
A39: Thunderstorms which generally produce the most intense hazards to aircraft are | B39: B | C39: Steady-state thunderstorms | D39: Squall line thunderstorms | E39: Warm front thunderstorms | H39: Weather | J39: ='end of unit questions'!J30 -> Weather MC Test - Key 2
A40: One in flight condition necessary for structural icing to form is… | B40: B | C40: Stratiform clouds | D40: Visible moisture | E40: Small temperature & dewpoint spread | H40: Weather | J40: =J39 -> Weather MC Test - Key 2
...

Sheet end of unit questions
A1: Question | B1: Answer | C1: Choice A | D1: Choice B | E1: Choice C | F1: Choice D | G1: Explaniation if needed | H1: Category | I1: Sub Category | J1: File Name
A2: What are the two types of clouds that pose hazards to unmanned aircraft operators? | B2: A | C2: Cumulonimbus and lenticular altocumulus | D2: Stratus and cirrus | E2: Cumulus and nimbus | F2: Altostratus and cumulus | H2: Weather | J2: Weather Part 2 MC - Key
A3: What is the main reason why frost is a flight safety hazard for unmanned aircraft? | B3: A | C3: Frost can cause the aircraft to lose lift and increase drag. | D3: Frost can damage the aircraft's engine. | E3: Frost can make the aircraft more difficult to control. | F3: Frost can make the aircraft more visible to other aircraft. | H3: Weather | J3: Weather Part 2 MC - Key
A4: What is the relationship between temperature and dew point? | B4: B | C4: Temperature is the amount of heat in the air, while dew point is the amount of moisture in the air. | D4: Temperature is the measure of how hot or cold the air is, while dew point is the temperature at which the air becomes saturated with moisture. | E4: Temperature is the measure of how fast the air is moving, while dew point is the measure of how much moisture is in the air. | F4: Temperature and dew point are not related. | H4: Weather | J4: Weather Part 2 MC - Key
A5: What is a temperature inversion and how does it affect weather and pollutants? | B5: B | C5: A temperature inversion is when the temperature decreases with altitude, leading to clear skies and good visibility. | D5: A temperature inversion is when the temperature increases with altitude, trapping weather and pollutants below. | E5: A temperature inversion is when the temperature remains constant with altitude, causing unpredictable weather patterns. | F5: A temperature inversion is a sudden drop in temperature at a specific altitude, leading to strong winds and turbulence. | H5: Weather | J5: Weather Part 2 MC - Key
A6: What is the main difference between a surface-based temperature inversion and a frontal inversion? | B6: C | C6: A surface-based inversion occurs during the day, while a frontal inversion occurs at night. | D6: A surface-based inversion is caused by warm air spreading over cold air, while a frontal inversion is caused by cold air spreading over warm air. | E6: A surface-based inversion is caused by the cooling of the ground at night, while a frontal inversion is caused by the interaction of different air masses. | F6: There is no significant difference between the two types of inversions. | H6: Weather | J6: Weather Part 2 MC - Key
A7: How does icing affect an unmanned aircraft's ability to fly? | B7: C | C7: Icing increases the aircraft's lift and reduces drag, making it easier to fly. | D7: Icing has no impact on an unmanned aircraft's ability to fly. | E7: Icing adds weight, reduces lift, and increases drag, making it harder to fly. | F7: Icing only affects the aircraft's appearance and does not affect its performance. | H7: Weather | J7: Weather Part 2 MC - Key
A8: What are the characteristics of standing lenticular altocumulus clouds and why should unmanned aircraft operators avoid them? | B8: C | C8: These clouds are small and fluffy, indicating calm air conditions. | D8: These clouds are large and dark, indicating strong winds and turbulence. | E8: These clouds are smooth and lens-shaped, indicating strong turbulence and should be avoided. | F8: These clouds are low-lying and often produce rain, making them hazardous to fly through. | H8: Weather | J8: Weather Part 2 MC - Key
A9: What is the recommended action for an unmanned aircraft operator if they encounter a frontal zone? | B9: C | C9: Continue flying as usual, as frontal zones are not a significant hazard. | D9: Increase altitude to avoid the frontal zone. | E9: Suspend operations until the front has passed through the area. | F9: Fly through the frontal zone quickly to minimize exposure. | H9: Weather | J9: Weather Part 2 MC - Key
A10: What is the main difference between a cumulonimbus cloud and a lenticular altocumulus cloud? | B10: A | C10: Cumulonimbus clouds are associated with thunderstorms, while lenticular altocumulus clouds are associated with mountain waves. | D10: Cumulonimbus clouds are small and fluffy, while lenticular altocumulus clouds are large and dark. | E10: Cumulonimbus clouds are formed by warm air rising, while lenticular altocumulus clouds are formed by cold air sinking. | F10: There is no significant difference between the two types of clouds. | H10: Weather | J10: Weather Part 2 MC - Key
A11: What is the recommended action for an unmanned aircraft operator if they see stratified clouds during a preflight visual assessment? | B11: B | C11: Suspend operations immediately, as stratified clouds indicate unstable air. | D11: Continue flying as usual, as stratified clouds indicate stable air. | E11: Increase altitude to avoid the stratified clouds. | F11: Fly through the stratified clouds quickly to minimize exposure. | H11: Weather | J11: Weather Part 2 MC - Key
A12: What is the minimum visibility requirement for unmanned flight operations from the ground control station? | B12: C | C12: 1 statute mile | D12: 2 statute miles | E12: 3 statute miles | F12: 5 statute miles | H12: Weather | J12: Weather Part 2 MC - Key
A13: What is the main reason why a drone operator should be aware of the wind direction and speed before flying in a mountainous area? | B13: C | C13: Wind can affect the aircraft's visibility. | D13: Wind can affect the aircraft's altitude. | E13: Wind can affect the aircraft's speed and direction. | F13: Wind can affect the aircraft's battery life. | H13: Weather | J13: Weather Part 2 MC - Key
... A19: What is the main reason why a drone operator should be aware of the dew point before flying? | B19: C | C19: To determine the best time of day to fly. | D19: To avoid flying in areas with high winds. | E19: To avoid flying in areas with fog or frost, which can be dangerous for unmanned aircraft. | F19: To determine the best altitude to fly. | H19: Weather | J19: Weather Part 2 MC - Key
A20: While operating around buildings, the Remote Pilot in Command should be aware of the creation of wind gusts that | B20: C | C20: enhance stability and imagery. | D20: increase performance of the aircraft. | E20: change rapidly in direction and speed causing turbulence. | H20: Weather | J20: Remaining Weather questions for James
A21: What should be obtained by the RPIC in order to receive a complete weather overview for the planned flight. | B21: B | C21: An outlook briefing | D21: A standard briefing | E21: Abbreviated briefing | H21: Weather | J21: Remaining Weather questions for James
A22: The predictions you considered during your preflight weather evaluation indicate that an unstable air mass is approaching your area. Which of those not be a problem for your upcoming operation? | B22: A | C22: Stratiform clouds | D22: Thunderstorms | E22: Turbulent conditions | H22: Weather | J22: Remaining Weather questions for James
A23: Which combination of atmospheric conditions will reduce aircraft takeoff and climb performance? | B23: C | C23: Low temperature, low relative humidity, and low density altitude. | D23: High temperature, low relative humidity, and low density altitude. | E23: High temperature, high relative humidity, and high density altitude. | H23: Weather | J23: Remaining Weather questions for James
A24: What is the primary reason why wind can cause turbulence around obstacles? | B24: A | C24: The wind is forced to change direction and speed around obstacles. | D24: The wind is blocked by obstacles, creating a vacuum. | E24: The wind is slowed down by obstacles, creating a pocket of calm air. | H24: Weather | J24: Weather MC Test - Key
A25: What is the standard temperature decrease per 1,000 feet above sea level? | B25: B | C25: 1°C | D25: 2°C | E25: 3.5°C | H25: Weather | J25: Weather MC Test - Key
A26: A TAF is for a 10-mile radius around the issuing airport. | B26: B | C26: True | D26: False | H26: Weather | J26: ='end of unit questions'!J27 -> Weather MC Test - Key 2
A27: A METAR does not contain information related to which of the following: | B27: C | C27: Altimeter | D27: Visibility | E27: Turbulence | H27: Weather | J27: =test!J51 -> Weather MC Test - Key 2
A28: A surface weather observation is a weather forecast. | B28: B | C28: True | D28: False | H28: Weather | J28: =test!J49 -> Weather MC Test - Key 2
A29: What is the primary reason why wind shear is considered a dangerous hazard to aircraft? | B29: C | C29: It can cause the aircraft to lose altitude rapidly. | D29: It can cause the aircraft to fly too fast. | E29: It can cause the aircraft to lose control. | H29: Weather | J29: =test!J41 -> Weather MC Test - Key 2
A30: What is the primary cause of low-level wind shear? | B30: C | C30: Changes in altitude. | D30: Changes in air pressure. | E30: Sudden changes in wind speed and direction. | H30: Weather | J30: =test!J38 -> Weather MC Test - Key 2
A31: One weather phenomenon which will always occur when flying across a front is | B31: C | C31: Stability of the air mass | D31: Type of precipitation | E31: Wind Direction | H31: Weather | J31: =test!J33 -> Weather MC Test - Key 2
A32: In which situation is fog likely to form? | B32: B | C32: A warm, moist air mass on the windward side of the mountains | D32: An air mass, moving in land from the coast in winter | E32: A light breeze blowing colder air out to the sea. | H32: Weather | J32: =test!J28 -> Weather MC Test - Key 2
A33: What is the primary reason why air density decreases as altitude increases? | B33: B | C33: The air gets colder at higher altitudes. | D33: There are fewer air molecules at higher altitudes. | E33: The air pressure increases at higher altitudes. | H33: Weather | J33: =test!J19 -> Weather MC Test - Key 2
A34: (Refer to figure 15 FAA-CT-8080-2H) At what time does the visibility improve to greater than 6 statute miles? | B34: B | C34: 051200Z | D34: 051600Z | E34: 051524Z | G34: At 051600Z, the TAF indicates "P6SM," meaning visibility improves to greater than 6 statute miles. | H34: Weather | I34: TAF | J34: TAF2 and KEY
A35: (Refer to figure 15 FAA-CT-8080-2H) What does "BECMG 0522/0524 20013G20KT" indicate? | B35: A | C35: A gradual change occurring between 0522Z and 0524Z. | D35: A temporary change lasting between 0522Z and 0524Z. | E35: A wind shift to 220° at 20 knots occurring at 0522Z. | G35: "BECMG" signifies a gradual change expected during the specified time period. | H35: Weather | I35: TAF | J35: TAF2 and KEY
A36: (Refer to figure 15 FAA-CT-8080-2H) What is the forecasted ceiling at 051200Z? | B36: B | C36: Overcast at 3,000 feet. | D36: Broken at 3,000 feet. | E36: Overcast at 2,000 feet. | G36: "BKN030" indicates a broken layer at 3,000 feet, which is the ceiling. | H36: Weather | I36: TAF | J36: TAF2 and KEY
A37: (Refer to figure 15 FAA-CT-8080-2H) During the period 0600Z to 0606Z, what is the probability of thunderstorms? | B37: C | C37: 60% | D37: 30% | E37: 40% | G37: "PROB40" indicates a 40% probability of thunderstorms and rain. | H37: Weather | I37: TAF | J37: TAF2 and KEY
A38: (Refer to figure 15 FAA-CT-8080-2H) What weather phenomenon is associated with "OVC008CB"? | B38: B | C38: Cumulonimbus clouds with fog. | D38: Cumulonimbus clouds with thunderstorms. | E38: Stratocumulus clouds with light rain. | G38: "CB" signifies cumulonimbus clouds, typically associated with thunderstorms. | H38: Weather | I38: TAF | J38: TAF2 and KEY
A39: (Refer to figure 15 FAA-CT-8080-2H) What visibility is expected during the "TEMPO 0513/0516" period? | B39: A | C39: 1 1/2 statute miles | D39: 5 statute miles | E39: Greater than 6 statute miles | G39: During this temporary period, visibility is reduced to 1 1/2SM due to mist, "BR." | H39: Weather | I39: TAF | J39: TAF2 and KEY
A40: (Refer to figure 15) What is the wind forecast for 0608Z? | B40: C | C40: 140° at 8 knots | D40: 200° at 13 knots, gusting to 20 knots | E40: 210° at 15 knots | G40: At 0608Z, the TAF indicates "21015KT," meaning wind from 210° at 15 knots. | H40: Weather | I40: TAF | J40: TAF2 and KEY
A41: (Refer to figure 15 FAA-CT-8080-2H) What does "P6SM SCT040" mean in the forecast starting at 0608Z? | B41: B | C41: Visibility less than 6 statute miles with scattered clouds at 4,000 feet. | D41: Visibility greater than 6 statute miles with scattered clouds at 4,000 feet. | E41: No significant weather with overcast skies at 4,000 feet. | G41: "P6SM" means visibility is greater than 6 statute miles, and "SCT040" indicates scattered clouds at 4,000 feet. | H41: Weather | I41: TAF | J41: TAF2 and KEY
A42: (Refer to Figure 15 FAA-CT-8080-2H) What is the forecast visibility for KMEM at the beginning of the TAF period (1218Z)? | B42: C | C42: 1 mile | D42: 3 statute miles | E42: 5 statute miles | H42: Weather | I42: TAF | J42: TAF Quiz- key
A43: (Refer to Figure 15 FAA-CT-8080-2H) According to the TAF, what type of weather is expected from 1220Z to 1222Z? | B43: A | C43: Thunderstorms with rain and overcast conditions | D43: Snow showers with overcast conditions | E43: Light rain with scattered clouds | H43: Weather | I43: TAF | J43: TAF Quiz- key
A44: (Refer to Figure 15 FAA-CT-8080-2H) What is the expected wind direction and speed at KMEM from 1222Z onward? | B44: C | C44: 020° at 8 knots | D44: 350° at 12 knots | E44: 330° at 15 knots with gusts to 20 knots | H44: Weather | I44: TAF | J44: TAF Quiz- key
A45: (Refer to Figure 15 FAA-CT-8080-2H) What is the forecast ceiling for KMEM from 1220Z to 1222Z? | B45: A | C45: 800 feet AGL | D45: 1,500 feet AGL | E45: 3,000 feet AGL | H45: Weather | I45: TAF | J45: TAF Quiz- key
...
